Workbook

Sheet PKL.
A1: CREATIVE COLLECTIONS LTD-2.
A2: Nishat Nagar , Tongi , Gazipur .
A3: PACKING LIST
A4: BULK PACK
E5: SIZE | G5: XS | H5: S | I5: M | J5: L | K5: XL | L5: XXL | M5: S/T | N5: M/T | O5: L/T | P5: XL/T | Q5: XXL+ | R5: XXL/T | S5: XXXL+ | T5: XS/T | U5: XS/P | V5: S/P | W5: M/P | X5: L/P | Y5: XL/P | Z5: XXL/P | AA5: XXXXL+
E6: N.W | G6: 0.27 | H6: 0.29 | I6: 0.31 | J6: 0.33 | K6: 0.35 | L6: 0.4 | M6: 0.32 | N6: 0.33 | O6: 0.36 | P6: 0.39 | Q6: 0.4 | R6: 0.43 | S6: 0.44 | T6: 0.31 | U6: 0.28 | V6: 0.29 | W6: 0.3 | X6: 0.33 | Y6: 0.35 | Z6: 0.39 | AA6: 0.48
E7: N.N.W | G7: =G6-0.01 -> 0.26 | H7: =H6-0.01 -> 0.28 | I7: =I6-0.01 -> 0.3 | J7: =J6-0.01 -> 0.32 | K7: =K6-0.01 -> 0.34 | L7: =L6-0.01 -> 0.39 | M7: =M6-0.01 -> 0.31 | N7: =N6-0.01 -> 0.32 | ... AA7: =AA6-0.01 -> 0.47
E8: EMPTY CTN WET | G8: 1/0.75/0.45
A9: BUYER : | D9: OLD NAVY
A10: STYLE : | D10: 1196178-00-2
A11: P. O. # : | D11: 62219966 | AA11: DC CODE : | AF11: OHO
A12: O/QTY : | D12: 814 | E12: PCS | AA12: PO # | AF12: =D11 -> 62219966
A13: SHIP QTY : | D13: =AF53 -> 818 | E13: PCS | AA13: SKU / Item | AF13: =+F22 -> 1196178-00-2
A14: EX/SHORT : | D14: =D13-D12 -> 4 | E14: PCS | AA14: Unit / Prepack | AF14: 20/0
A15: CTN QTY : | D15: =D53 -> 37 | E15: CTNS | AA15: CARTON | AF15: 01 of 37
A16: CTN MEAS. : | D16: 58.67 X 38.48 X 29.72 CM.G81
A17: CTN MEAS. : | D17: 58.67 X 38.48 X 14.86 CM.G82
A18: CTN MEAS. : | D18: 38.48 X 29.34 X 14.86 CM.G84
A19: CTN MEAS. : | D19: 29.34 X 19.25 X 14.86 CM.G85
A20: CTN | C20: CTN | D20: CTN QTY | E20: COLOR | F20: BULK | G20: SIZE | AE20: QTY PER CTN | AF20: TOTAL QTY | AG20: GROSS WEIGHT | AH20: NET WEIGHT
A21: NO | C21: MES: | G21: XS | H21: S | I21: M | J21: L | K21: XL | L21: XXL | M21: S/T | N21: M/T | O21: L/T | P21: XL/T | Q21: XXL+ | R21: XXL/T | S21: XXXL+ | T21: XS/T | U21: XS/P | V21: S/P | W21: M/P | X21: L/P | Y21: XL/P | Z21: XXL/P | AA21: XXXXL+
A22: 1 | B22: =+D22 -> 1 | C22: G82 | D22: 1 | E22: RINSE-00-2 | F22: =+D10 -> 1196178-00-2 | G22: 25 | AE22: =SUM(G22:AD22) -> 25 | AF22: =AE22*D22 -> 25 | AG22: =+G6*AE22+0.75 -> 7.5 | AH22: =AG22-0.75 -> 6.75
A23: =+B22+1 -> 2 | B23: =+B22+D23 -> 2 | C23: G84 | D23: 1 | G23: 12 | AE23: =SUM(G23:AD23) -> 12 | AF23: =AE23*D23 -> 12 | AG23: =+G6*AE23+0.45 -> 3.69 | AH23: =AG23-0.45 -> 3.24
A24: =+B23+1 -> 3 | B24: =+B23+D24 -> 4 | C24: G81 | D24: 2 | H24: 55 | AE24: =SUM(G24:AD24) -> 55 | AF24: =AE24*D24 -> 110 | AG24: =+H6*AE24+1 -> 16.95 | AH24: =AG24-1 -> 15.95
A25: =+B24+1 -> 5 | B25: =+B24+D25 -> 7 | C25: G81 | D25: 3 | I25: 50 | AE25: =SUM(G25:AD25) -> 50 | AF25: =AE25*D25 -> 150 | AG25: =+I6*AE25+1 -> 16.5 | AH25: =AG25-1 -> 15.5
A26: =+B25+1 -> 8 | B26: =+B25+D26 -> 8 | C26: G82 | D26: 1 | I26: 20 | AE26: =SUM(G26:AD26) -> 20 | AF26: =AE26*D26 -> 20 | AG26: =+I6*AE26+0.45 -> 6.65 | AH26: =AG26-0.45 -> 6.2
A27: =+B26+1 -> 9 | B27: =+B26+D27 -> 11 | C27: G81 | D27: 3 | J27: 45 | AE27: =SUM(G27:AD27) -> 45 | AF27: =AE27*D27 -> 135 | AG27: =+J6*AE27+1 -> 15.85 | AH27: =AG27-1 -> 14.85
A28: =+B27+1 -> 12 | B28: =+B27+D28 -> 12 | C28: G82 | D28: 1 | J28: 20 | AE28: =SUM(G28:AD28) -> 20 | AF28: =AE28*D28 -> 20 | AG28: =+J6*AE28+0.75 -> 7.35 | AH28: =AG28-0.75 -> 6.6
A29: =+B28+1 -> 13 | B29: =+B28+D29 -> 14 | C29: G81 | D29: 2 | K29: 44 | AE29: =SUM(G29:AD29) -> 44 | AF29: =AE29*D29 -> 88 | AG29: =+K6*AE29+1 -> 16.4 | AH29: =AG29-1 -> 15.4
A30: =+B29+1 -> 15 | B30: =+B29+D30 -> 15 | C30: G84 | D30: 1 | K30: 8 | AE30: =SUM(G30:AD30) -> 8 | AF30: =AE30*D30 -> 8 | AG30: =+K6*AE30+0.45 -> 3.25 | AH30: =AG30-0.45 -> 2.8
A31: =+B30+1 -> 16 | B31: =+B30+D31 -> 17 | C31: G82 | D31: 2 | L31: 16 | AE31: =SUM(G31:AD31) -> 16 | AF31: =AE31*D31 -> 32 | AG31: =+L6*AE31+0.75 -> 7.15 | AH31: =AG31-0.75 -> 6.4
A32: =+B31+1 -> 18 | B32: =+B31+D32 -> 18 | C32: G84 | D32: 1 | M32: 12 | AE32: =SUM(G32:AD32) -> 12 | AF32: =AE32*D32 -> 12 | AG32: =+M6*AE32+0.45 -> 4.29 | AH32: =AG32-0.45 -> 3.84
A33: =+B32+1 -> 19 | B33: =+B32+D33 -> 19 | C33: G82 | D33: 1 | N33: 20 | AE33: =SUM(G33:AD33) -> 20 | AF33: =AE33*D33 -> 20 | AG33: =+N6*AE33+0.75 -> 7.35 | AH33: =AG33-0.75 -> 6.6
A34: =+B33+1 -> 20 | B34: =+B33+D34 -> 20 | C34: G85 | D34: 1 | N34: 5 | AE34: =SUM(G34:AD34) -> 5 | AF34: =AE34*D34 -> 5 | AG34: =+N7*AE34+0.75 -> 2.35 | AH34: =AG34-0.75 -> 1.6
A35: =+B34+1 -> 21 | B35: =+B34+D35 -> 21 | C35: G82 | D35: 1 | O35: 20 | AE35: =SUM(G35:AD35) -> 20 | AF35: =AE35*D35 -> 20 | AG35: =+O6*AE35+0.75 -> 7.95 | AH35: =AG35-0.75 -> 7.2
A36: =+B35+1 -> 22 | B36: =+B35+D36 -> 22 | C36: G84 | D36: 1 | O36: 10 | AE36: =SUM(G36:AD36) -> 10 | AF36: =AE36*D36 -> 10 | AG36: =+O6*AE36+0.45 -> 4.05 | AH36: =AG36-0.45 -> 3.6
A37: =+B36+1 -> 23 | B37: =+B36+D37 -> 23 | C37: G82 | D37: 1 | P37: 18 | AE37: =SUM(G37:AD37) -> 18 | AF37: =AE37*D37 -> 18 | AG37: =+P6*AE37+0.75 -> 7.77 | AH37: =AG37-0.75 -> 7.02
A38: =+B37+1 -> 24 | B38: =+B37+D38 -> 24 | C38: G84 | D38: 1 | P38: 8 | AE38: =SUM(G38:AD38) -> 8 | AF38: =AE38*D38 -> 8 | AG38: =+P6*AE38+0.45 -> 3.57 | AH38: =AG38-0.45 -> 3.12
A39: =+B38+1 -> 25 | B39: =+B38+D39 -> 25 | C39: G82 | D39: 1 | Q39: 16 | AE39: =SUM(G39:AD39) -> 16 | AF39: =AE39*D39 -> 16 | AG39: =+Q6*AE39+0.75 -> 7.15 | AH39: =AG39-0.75 -> 6.4
A40: =+B39+1 -> 26 | B40: =+B39+D40 -> 26 | C40: G84 | D40: 1 | Q40: 7 | AE40: =SUM(G40:AD40) -> 7 | AF40: =AE40*D40 -> 7 | AG40: =+Q6*AE40+0.25 -> 3.05 | AH40: =AG40-0.25 -> 2.8
...

Sheet sum
A1: CREATIVE COLLECTIONS LIMITED (UNIT= 02)
A2: Nishatnagar,Tongi,Gazipur
A3: PACKING LIST SUMMARY
A5: BUYER | B5: OLD NAVY
A6: STYLE | B6: 509483 | H6: DATE | I6: 46260
A8: DC | B8: PO NO | C8: SEASON | D8: COLOR/CODE | E8: ORD/QTY | F8: SHIP/QTY | G8: EXCES | H8: SHORT | I8: PER (%) | J8: CTNS
A9: CAO | B9: ='PKL.'!D11 -> 62219966 | C9: Hol'26 | D9: =+'PKL.'!E22 -> RINSE-00-2 | E9: =+'PKL.'!AF57 -> 814 | F9: =+'PKL.'!AF58 -> 818 | G9: =+F9-E9 -> 4 | H9: 0 | I9: =+G9/E9 -> 0.0049140049 | J9: =+'PKL.'!D53 -> 37
D11: TOTAL | E11: =SUM(E9:E10) -> 814 | F11: =SUM(F9:F10) -> 818 | G11: =SUM(G9:G10) -> 4 | H11: =SUM(H9:H10) -> 0 | I11: =+G11/E11 -> 0.0049140049 | J11: =SUM(J9:J10) -> 37
B17: SERIAL NO | D17: PENDING ISSUE | E17: YES | F17: NO | G17: REMARKS
B18: 1 | D18: %ISSUE
B19: 2 | D19: GPT
B20: 3 | D20: TOP
B21: 4 | D21: SHADE BAND
B22: 5 | D22: GTS/YTS
B23: 6 | D23: UP DATE DC PO
B24: 7 | D24: TRIM CARD
B25: 8 | D25: FA CTN QTY
B26: 9 | D26: CHECK QTY
B27: 10 | D27: VSL DATE
D28: ITEM
A41: FA AUDITOR | D41: PACKING INCHARGE | I41: FINISHING MANAGER
