Workbook

Sheet PKL.
A1: CREATIVE COLLECTIONS LTD-2.
A2: Nishat Nagar , Tongi , Gazipur .
A3: PACKING LIST
A4: BULK PACK
C5: SIZE | E5: XS REG | F5: S REG | G5: M REG | H5: L REG | I5: XL REG | J5: XXL REG
C6: N.W | E6: 0.11 | F6: 0.12 | G6: 0.13 | H6: 0.14 | I6: 0.14 | J6: 0.18
C7: N.N.W | E7: =E6-0.01 -> 0.1 | F7: =F6-0.01 -> 0.11 | G7: =G6-0.01 -> 0.12 | H7: =H6-0.01 -> 0.13 | I7: =I6-0.01 -> 0.13 | J7: =J6-0.01 -> 0.17
C8: EMPTY CTN WET | E8: 1/0.75/0.45
A9: BUYER : | D9: GAP
A10: STYLE : | D10: 1172809-12-1
A11: P. O. # : | D11: 62209540 | J11: DC CODE : | N11: LVO
A12: O/QTY : | D12: 2100 | E12: PCS | J12: PO # | N12: =D11 -> 62209540
A13: SHIP QTY : | D13: =N39 -> 2144 | E13: PCS | J13: SKU / Item | N13: 912548
A14: EX/SHORT : | D14: =D13-D12 -> 44 | E14: PCS | J14: Unit / Prepack | N14: 20/0
A15: CTN QTY : | D15: =D39 -> 32 | E15: CTNS | J15: CARTON | N15: 01 of 32
A16: CTN MEAS. : | D16: 58.67 X 38.48 X 29.72 CM.G81
A17: CTN MEAS. : | D17: 58.67 X 38.48 X 14.86 CM.G82
A18: CTN MEAS. : | D18: 38.48 X 29.34 X 14.86 CM.G84
A19: CTN MEAS. : | D19: 29.34 X 19.25 X 14.86 CM.G85
A20: CTN | C20: CTN | D20: CTN QTY | E20: COLOR | F20: BULK | G20: SIZE | M20: QTY PER CTN | N20: TOTAL QTY | O20: GROSS WEIGHT | P20: NET WEIGHT
A21: NO | C21: MES: | G21: =+E5 -> XS REG | H21: =+F5 -> S REG | I21: =+G5 -> M REG | J21: =+H5 -> L REG | K21: =+I5 -> XL REG | L21: =+J5 -> XXL REG
A22: =1 -> 1 | B22: =+D22 -> 1 | C22: G81 | D22: 1 | E22: WICKER-12-1 | F22: =+D10 -> 1172809-12-1 | G22: 105 | M22: =SUM(G22:J22) -> 105 | N22: =M22*D22 -> 105 | O22: =+E6*M22+1 -> 12.55 | P22: =O22-1 -> 11.55
A23: =+B22+1 -> 2 | B23: =+B22+D23 -> 2 | C23: G82 | D23: 1 | G23: 50 | M23: =SUM(G23:J23) -> 50 | N23: =M23*D23 -> 50 | O23: =+E6*M23+0.75 -> 6.25 | P23: =O23-0.75 -> 5.5
A24: =+B23+1 -> 3 | B24: =+B23+D24 -> 3 | C24: G84 | D24: 1 | G24: 25 | M24: =SUM(G24:J24) -> 25 | N24: =M24*D24 -> 25 | O24: =+E6*M24+0.45 -> 3.2 | P24: =O24-0.45 -> 2.75
A25: =+B24+1 -> 4 | B25: =+B24+D25 -> 4 | C25: G85 | D25: 1 | G25: 10 | M25: =SUM(G25:J25) -> 10 | N25: =M25*D25 -> 10 | O25: =+E6*M25+0.25 -> 1.35 | P25: =O25-0.25 -> 1.1
A26: =+B25+1 -> 5 | B26: =+B25+D26 -> 8 | C26: G81 | D26: 4 | H26: 105 | M26: =SUM(G26:J26) -> 105 | N26: =M26*D26 -> 420 | O26: =+F6*M26+1 -> 13.6 | P26: =O26-1 -> 12.6
A27: =+B26+1 -> 9 | B27: =+B26+D27 -> 9 | C27: G84 | D27: 1 | H27: 26 | M27: =SUM(G27:J27) -> 26 | N27: =M27*D27 -> 26 | O27: =+F6*M27+0.45 -> 3.57 | P27: =O27-0.45 -> 3.12
A28: =+B27+1 -> 10 | B28: =+B27+D28 -> 10 | C28: G85 | D28: 1 | H28: 10 | M28: =SUM(G28:J28) -> 10 | N28: =M28*D28 -> 10 | O28: =+F6*M28+0.25 -> 1.45 | P28: =O28-0.25 -> 1.2
A29: =+B28+1 -> 11 | B29: =+B28+D29 -> 14 | C29: G81 | D29: 4 | I29: 90 | M29: =SUM(G29:J29) -> 90 | N29: =M29*D29 -> 360 | O29: =+G6*M29+1 -> 12.7 | P29: =O29-1 -> 11.7
A30: =+B29+1 -> 15 | B30: =+B29+D30 -> 16 | C30: G82 | D30: 2 | I30: 40 | M30: =SUM(G30:J30) -> 40 | N30: =M30*D30 -> 80 | O30: =+G6*M30+0.75 -> 5.95 | P30: =O30-0.75 -> 5.2
A31: =+B30+1 -> 17 | B31: =+B30+D31 -> 20 | C31: G81 | D31: 4 | J31: 90 | M31: =SUM(G31:L31) -> 90 | N31: =M31*D31 -> 360 | O31: =+H6*M31+1 -> 13.6 | P31: =O31-1 -> 12.6
A32: =+B31+1 -> 21 | B32: =+B31+D32 -> 21 | C32: G82 | D32: 1 | J32: 36 | M32: =SUM(G32:L32) -> 36 | N32: =M32*D32 -> 36 | O32: =+H6*M32+0.75 -> 5.79 | P32: =O32-0.75 -> 5.04
A33: =+B32+1 -> 22 | B33: =+B32+D33 -> 25 | C33: G81 | D33: 4 | K33: 75 | M33: =SUM(G33:L33) -> 75 | N33: =M33*D33 -> 300 | O33: =+I6*M33+1 -> 11.5 | P33: =O33-1 -> 10.5
A34: =+B33+1 -> 26 | B34: =+B33+D34 -> 26 | C34: G82 | D34: 1 | K34: 34 | M34: =SUM(G34:L34) -> 34 | N34: =M34*D34 -> 34 | O34: =+I6*M34+0.75 -> 5.51 | P34: =O34-0.75 -> 4.76
A35: =+B34+1 -> 27 | B35: =+B34+D35 -> 29 | C35: G81 | D35: 3 | L35: 70 | M35: =SUM(G35:L35) -> 70 | N35: =M35*D35 -> 210 | O35: =+J6*M35+1 -> 13.6 | P35: =O35-1 -> 12.6
A36: =+B35+1 -> 30 | B36: =+B35+D36 -> 30 | C36: G81 | D36: 1 | L36: 62 | M36: =SUM(G36:L36) -> 62 | N36: =M36*D36 -> 62 | O36: =+J6*M36+1 -> 12.16 | P36: =O36-1 -> 11.16
A37: =+B36+1 -> 31 | B37: =+B36+D37 -> 32 | C37: G82 | D37: 2 | L37: 28 | M37: =SUM(G37:L37) -> 28 | N37: =M37*D37 -> 56 | O37: =+J6*M37+0.75 -> 5.79 | P37: =O37-0.75 -> 5.04
A39: TOTAL | D39: =SUM(D22:D38) -> 32 | E39: CTNS | G39: =+N25+N24+N23+N22 -> 190 | H39: =+N28+N27+N26 -> 456 | I39: =+N30+N29 -> 440 | J39: =+N32+N31 -> 396 | K39: =+N34+N33 -> 334 | L39: =+N37+N35+N36 -> 328 | N39: =SUM(N22:N38) -> 2144 | O39: PCS
E41: SUMMARY
E42: SIZE | G42: =+G21 -> XS REG | H42: =+H21 -> S REG | I42: =+I21 -> M REG | J42: =+J21 -> L REG | K42: =+K21 -> XL REG | L42: =+L21 -> XXL REG | N42: TOTAL
...

Sheet sum
A1: CREATIVE COLLECTIONS LIMITED (UNIT= 02)
A2: Nishatnagar,Tongi,Gazipur
A3: PACKING LIST SUMMARY
A5: BUYER | B5: GAP
A6: STYLE | B6: 912548 | C6: D92406 | H6: DATE | I6: 8/3/2026
A8: DC | B8: PO NO | C8: SEASON | D8: COLOR/CODE | E8: ORD/QTY | F8: SHIP/QTY | G8: EXCES | H8: SHORT | I8: PER (%) | J8: CTNS
A9: CAO | B9: =+PKL.!D11 -> 62209540 | C9: Fall'26 | D9: =PKL.!E22 -> WICKER-12-1 | E9: =PKL.!N43 -> 2100 | F9: =PKL.!N44 -> 2144 | G9: =F9-E9 -> 44 | H9: 0 | I9: =+G9/E9 -> 0.020952381 | J9: =PKL.!D39 -> 32
D11: TOTAL | E11: =SUM(E9:E10) -> 2100 | F11: =SUM(F9:F10) -> 2144 | G11: =SUM(G9:G10) -> 44 | H11: =SUM(H9:H10) -> 0 | I11: =+G11/E11 -> 0.020952381 | J11: =SUM(J9:J10) -> 32
B17: SERIAL NO | D17: PENDING ISSUE | E17: YES | F17: NO | G17: REMARKS
B18: 1 | D18: %ISSUE
B19: 2 | D19: GPT
B20: 3 | D20: TOP
B21: 4 | D21: SHADE BAND
B22: 5 | D22: GTS/YTS
B23: 6 | D23: UP DATE DC PO
B24: 7 | D24: TRIM CARD
B25: 8 | D25: FA CTN QTY
B26: 9 | D26: CHECK QTY
B27: 10 | D27: VSL DATE
D28: ITEM
A41: FA AUDITOR | D41: PACKING INCHARGE | I41: FINISHING MANAGER
