Workbook

Sheet PKL.
A1: CREATIVE COLLECTIONS LTD-2.
A2: Nishat Nagar , Tongi , Gazipur .
A3: PACKING LIST
A4: MULTY PACK ( N )
E5: SIZE | G5: XS REG | H5: S REG | I5: M REG | J5: L REG | K5: XL REG | L5: XXL REG
E6: N.W | G6: 0.11 | H6: 0.12 | I6: 0.13 | J6: 0.14 | K6: 0.14 | L6: 0.18
E7: N.N.W | G7: =G6-0.01 -> 0.1 | H7: =H6-0.01 -> 0.11 | I7: =I6-0.01 -> 0.12 | J7: =J6-0.01 -> 0.13 | K7: =K6-0.01 -> 0.13 | L7: =L6-0.01 -> 0.17
E8: EMPTY CTN WET | G8: 1/0.75/0.45
A9: BUYER : | D9: GAP
A10: STYLE : | D10: 1172809-13-1
A11: P. O. # : | D11: 62199028 | L11: DC CODE : | Q11: TDC
A12: O/QTY : | D12: 153 | E12: PCS | L12: PO # | Q12: =D11 -> 62199028
A13: SHIP QTY : | D13: =Q26 -> 153 | E13: PCS | L13: SKU / Item | Q13: =F22 -> 7021483
A14: EX/SHORT : | D14: =D13-D12 -> 0 | E14: PCS | L14: Unit / Prepack | Q14: 48/6
A15: CTN QTY : | D15: =D26 -> 3 | E15: CTNS | L15: CARTON | Q15: 01 of 15
A16: CTN MEAS. : | D16: 58.67 X 38.48 X 29.72 CM.G81
A17: CTN MEAS. : | D17: 58.67 X 38.48 X 14.86 CM.G82
A18: CTN MEAS. : | D18: 38.48 X 29.34 X 14.86 CM.G84
A19: CTN MEAS. : | D19: 29.34 X 19.25 X 14.86 CM.G8XS
A20: CTN | C20: CTN | D20: CTN QTY | E20: COLOR | F20: PREPACK STECKER | G20: SIZE | M20: PER BLST | P20: QTY PER CTN | Q20: TOTAL QTY | R20: GROSS WEIGHT | S20: NET WEIGHT
A21: NO | C21: MES: | G21: =+G5 -> XS REG | H21: =+H5 -> S REG | I21: =+I5 -> M REG | J21: =+J5 -> L REG | K21: =+K5 -> XL REG | L21: =+L5 -> XXL REG
A22: 1 | B22: =+D22 -> 1 | C22: G81 | D22: 1 | E22: WALDEN GREEN-13-1 | F22: 7021483 | G22: 1 | H22: 2 | I22: 2 | J22: 2 | K22: 1 | L22: 1 | M22: =SUM(G22:L22) -> 9 | N22: X | O22: 11 | P22: =+O22*M22 -> 99 | Q22: =P22*D22 -> 99 | R22: =+J6*P22+1 -> 14.86 | S22: =R22-1 -> 13.86
A23: =+B22+1 -> 2 | B23: =+B22+D23 -> 2 | C23: G82 | D23: 1 | F23: 7021483 | G23: 1 | H23: 2 | I23: 2 | J23: 2 | K23: 1 | L23: 1 | M23: =SUM(G23:L23) -> 9 | N23: X | O23: 5 | P23: =+O23*M23 -> 45 | Q23: =P23*D23 -> 45 | R23: =+J6*P23+0.75 -> 7.05 | S23: =R23-0.75 -> 6.3
A24: =+B23+1 -> 3 | B24: =+B23+D24 -> 3 | C24: G85 | D24: 1 | F24: 7021483 | G24: 1 | H24: 2 | I24: 2 | J24: 2 | K24: 1 | L24: 1 | M24: =SUM(G24:L24) -> 9 | N24: X | O24: 1 | P24: =+O24*M24 -> 9 | Q24: =P24*D24 -> 9 | R24: =+J6*P24+0.25 -> 1.51 | S24: =R24-0.25 -> 1.26
A26: TOTAL | D26: =SUM(D22:D25) -> 3 | E26: CTNS | G26: =+D22*G22*O22+O23*G23*D23+G24*D24*O24 -> 17 | H26: =+D22*H22*O22+O23*H23*D23+H24*D24*O24 -> 34 | I26: =+D22*I22*O22+O23*I23*D23+I24*D24*O24 -> 34 | J26: =+D22*J22*O22+O23*J23*D23+J24*D24*O24 -> 34 | K26: =D22*K22*O22+D23*K23*O23+D24*K24*O24 -> 17 | L26: =D22*L22*O22+D23*L23*O23+D24*L24*O24 -> 17 | Q26: =SUM(Q22:Q25) -> 153 | R26: PCS
A28: SINGLE PACK
A29: BUYER : | D29: =+D9 -> GAP
A30: STYLE : | D30: =+D10 -> 1172809-13-1
A31: P. O. # : | D31: =+D11 -> 62199028
A32: O/QTY : | D32: 14 | E32: PCS | L32: PO # | Q32: =D31 -> 62199028
A33: SHIP QTY : | D33: =Q41 -> 14 | E33: PCS | L33: SKU / Item | Q33: =F38 -> MIXED
A34: EX/SHORT : | D34: =D33-D32 -> 0 | E34: PCS | L34: Unit / Prepack | Q34: 80/40
A35: CTN QTY : | D35: =D41 -> 2 | E35: CTNS | L35: CARTON | Q35: 04 of 15
A36: CTN | C36: CTN | D36: CTN QTY | E36: COLOR | F36: PREPACK STECKER | G36: SIZE | P36: QTY PER CTN | Q36: TOTAL QTY | R36: GROSS WEIGHT | S36: NET WEIGHT
A37: NO | C37: MES: | G37: =+G21 -> XS REG | H37: =+H21 -> S REG | I37: =+I21 -> M REG | J37: =+J21 -> L REG | K37: =+K21 -> XL REG | L37: =+L21 -> XXL REG
A38: =+D26+1 -> 4 | B38: =+D26+D38 -> 4 | C38: G85 | D38: 1 | E38: =+E22 -> WALDEN GREEN-13-1 | F38: MIXED | G38: 2 | H38: 3 | P38: =SUM(G38:L38)*2 -> 10 | Q38: =P38*D38 -> 10 | R38: =+H6*P38+0.25 -> 1.45 | S38: =R38-0.25 -> 1.2
A39: =+B38+1 -> 5 | B39: =+B38+D39 -> 5 | C39: G85 | D39: 1 | F39: MIXED | I39: 1 | J39: 1 | P39: =SUM(G39:L39)*2 -> 4 | Q39: =P39*D39 -> 4 | R39: =+J6*P39+0.25 -> 0.81 | S39: =R39-0.25 -> 0.56
A41: TOTAL | D41: =SUM(D38:D40) -> 2 | E41: CTNS | G41: =+G38*2 -> 4 | H41: =+H38*2 -> 6 | I41: =+I39*2 -> 2 | J41: =+J39*2 -> 2 | K41: 0 | L41: 0 | Q41: =SUM(Q38:Q40) -> 14 | R41: PCS
A43: BULK PACK
A44: BUYER : | D44: =+D9 -> GAP
...

Sheet sum
A1: CREATIVE COLLECTIONS LIMITED (UNIT= 02)
A2: Nishatnagar,Tongi,Gazipur
A3: PACKING LIST SUMMARY
A5: BUYER | B5: GAP OUT
A6: STYLE | B6: 1184607 | C6: D97808 | H6: DATE | I6: 7/31/2026
A8: DC | B8: PO NO | C8: SEASON | D8: COLOR/CODE | E8: ORD/QTY | F8: SHIP/QTY | G8: EXCES | H8: SHORT | I8: PER (%) | J8: CTNS
A9: TDC | B9: =+PKL.!D11 -> 62199028 | C9: Hol'26 | D9: =+PKL.!E22 -> WALDEN GREEN-13-1 | E9: =+PKL.!Q64 -> 1041 | F9: =+PKL.!Q65 -> 1059 | G9: =F9-E9 -> 18 | H9: 0 | I9: =+G9/E9 -> 0.017291066 | J9: =+PKL.!D26+PKL.!D41+PKL.!D60 -> 15
D11: TOTAL | E11: =SUM(E9:E10) -> 1041 | F11: =SUM(F9:F10) -> 1059 | G11: =SUM(G9:G10) -> 18 | H11: =SUM(H9:H10) -> 0 | I11: =+G11/E11 -> 0.017291066 | J11: =SUM(J9:J10) -> 15
B17: SERIAL NO | D17: PENDING ISSUE | E17: YES | F17: NO | G17: REMARKS
B18: 1 | D18: %ISSUE
B19: 2 | D19: GPT
B20: 3 | D20: TOP
B21: 4 | D21: SHADE BAND
B22: 5 | D22: GTS/YTS
B23: 6 | D23: UP DATE DC PO
B24: 7 | D24: TRIM CARD
B25: 8 | D25: FA CTN QTY
B26: 9 | D26: CHECK QTY
B27: 10 | D27: VSL DATE
D28: ITEM
A41: FA AUDITOR | D41: PACKING INCHARGE | I41: FINISHING MANAGER

Sheet Sheet2
E2: =+[1]PKL.!$G$40 -> XS | F2: =+[1]PKL.!$H$40 -> S | G2: M | H2: L | I2: XL | J2: XXL | K2: LH | L2: XL H | M2: XXLH
A3: =+PKL.!D46 -> 62199028 | B3: =+PKL.!E53 -> WALDEN GREEN-13-1 | D3: =+PKL.!E64 -> ORDER QTY | E3: =+PKL.!G64 -> 125 | F3: =+PKL.!H64 -> 240 | G3: =+PKL.!I64 -> 221 | H3: =+PKL.!J64 -> 203 | I3: =+PKL.!#REF! -> #REF! | N3: =SUM(E3:I3) -> #REF!
A4: =+[1]PKL.!$D$8 -> C7EO7MA | B4: DARK GREY-00-2 | D4: =+D3 -> ORDER QTY | E4: =+[1]PKL.!$G$42 -> 208 | F4: =+[1]PKL.!$H$42 -> 553 | G4: =+[1]PKL.!$I$42 -> 556 | H4: =+[1]PKL.!$J$42 -> 561 | I4: =+[1]PKL.!$K$42 -> 373 | J4: =+[1]PKL.!$L$42 -> 85 | K4: =+[1]PKL.!$M$42 -> 29 | L4: =+[1]PKL.!$N$42 -> 44 | M4: =+[1]PKL.!$O$42 -> 37 | N4: =SUM(E4:M4) -> 2446
D5: TOTAL | E5: =+E4+E3 -> 333 | F5: =+F4+F3 -> 793 | G5: =+G4+G3 -> 777 | H5: =+H4+H3 -> 764 | I5: =+I4+I3 -> #REF! | J5: =+J4+J3 -> 85 | K5: =+K4+K3 -> 29 | L5: =+L4+L3 -> 44 | ... N5: =+N4+N3 -> #REF!
A6: =+A3 -> 62199028 | B6: =+B3 -> WALDEN GREEN-13-1 | D6: =+PKL.!E65 -> SHIP QTY | E6: =+PKL.!G65 -> 125 | F6: =+PKL.!H65 -> 244 | G6: =+PKL.!I65 -> 224 | H6: =+PKL.!J65 -> 208 | I6: =+PKL.!#REF! -> #REF! | N6: =SUM(E6:I6) -> #REF!
A7: =+A4 -> C7EO7MA | B7: =+B4 -> DARK GREY-00-2 | D7: =+D6 -> SHIP QTY | E7: =+E4 -> 208 | F7: =+F4 -> 553 | G7: =+G4 -> 556 | H7: =+H4 -> 561 | I7: =+I4 -> 373 | J7: =+J4 -> 85 | K7: =+K4 -> 29 | L7: =+L4 -> 44 | ... N7: =+N4 -> 2446
D8: =+D5 -> TOTAL | E8: =+E7+E6 -> 333 | F8: =+F7+F6 -> 797 | G8: =+G7+G6 -> 780 | H8: =+H7+H6 -> 769 | I8: =+I7+I6 -> #REF! | J8: =+J7+J6 -> 85 | K8: =+K7+K6 -> 29 | L8: =+L7+L6 -> 44 | ... N8: =+N7+N6 -> #REF!
E9: =+E8-E5 -> 0 | F9: =+F8-F5 -> 4 | G9: =+G8-G5 -> 3 | H9: =+H8-H5 -> 5 | I9: =+I8-I5 -> #REF! | J9: =+J8-J5 -> 0 | K9: =+K8-K5 -> 0 | L9: =+L8-L5 -> 0 | ... N9: =+N8-N5 -> #REF!
E11: =+E2 -> XS | F11: =+F2 -> S | G11: =+G2 -> M | H11: =+H2 -> L | I11: =+I2 -> XL | J11: =+J2 -> XXL | K11: =+K2 -> LH | L11: =+L2 -> XL H | M11: =+M2 -> XXLH
A12: =+A3 -> 62199028 | B12: =+PKL.!#REF! -> #REF! | D12: =+D3 -> ORDER QTY | E12: =+PKL.!#REF! -> #REF! | F12: =+PKL.!#REF! -> #REF! | G12: =+PKL.!#REF! -> #REF! | H12: =+PKL.!#REF! -> #REF! | I12: =+PKL.!#REF! -> #REF! | J12: =+PKL.!#REF! -> #REF! | K12: =+PKL.!#REF! -> #REF! | L12: =+PKL.!#REF! -> #REF! | M12: =+PKL.!#REF! -> #REF! | N12: =SUM(E12:M12) -> #REF!
A13: =+A4 -> C7EO7MA | B13: ORANGE TEAL PLAID -02-2 | D13: =+D4 -> ORDER QTY | E13: =+[1]PKL.!$G$109 -> 303 | F13: =+[1]PKL.!$H$109 -> 808 | G13: =+[1]PKL.!$I$109 -> 812 | H13: =+[1]PKL.!$J$109 -> 819 | I13: =+[1]PKL.!$K$109 -> 545 | J13: =+[1]PKL.!$L$109 -> 124 | K13: =+[1]PKL.!$M$109 -> 42 | L13: 65 | M13: =+[1]PKL.!$O$109 -> 54 | N13: =SUM(E13:M13) -> 3572
D14: =+D5 -> TOTAL | E14: =SUM(E12:E13) -> #REF! | F14: =SUM(F12:F13) -> #REF! | G14: =SUM(G12:G13) -> #REF! | H14: =SUM(H12:H13) -> #REF! | I14: =SUM(I12:I13) -> #REF! | J14: =SUM(J12:J13) -> #REF! | K14: =SUM(K12:K13) -> #REF! | L14: =SUM(L12:L13) -> #REF! | ... N14: =SUM(N12:N13) -> #REF!
A15: =+A12 -> 62199028 | B15: =+B12 -> #REF! | D15: =+D6 -> SHIP QTY | E15: =+PKL.!#REF! -> #REF! | F15: =+PKL.!#REF! -> #REF! | G15: =+PKL.!#REF! -> #REF! | H15: =+PKL.!#REF! -> #REF! | I15: =+PKL.!#REF! -> #REF! | N15: =SUM(E15:M15) -> #REF!
A16: =+A13 -> C7EO7MA | B16: =+B13 -> ORANGE TEAL PLAID -02-2 | D16: =+D7 -> SHIP QTY | E16: =+[1]PKL.!$G$110 -> 303 | F16: 808 | G16: 812 | H16: 819 | I16: 545 | J16: 124 | K16: 42 | L16: 65 | M16: 54 | N16: =SUM(E16:M16) -> 3572
D17: =+D8 -> TOTAL | E17: =SUM(E15:E16) -> #REF! | F17: =SUM(F15:F16) -> #REF! | G17: =SUM(G15:G16) -> #REF! | H17: =SUM(H15:H16) -> #REF! | I17: =SUM(I15:I16) -> #REF! | J17: =SUM(J15:J16) -> 124 | K17: =SUM(K15:K16) -> 42 | L17: =SUM(L15:L16) -> 65 | ... N17: =SUM(N15:N16) -> #REF!
E18: =+E17-E14 -> #REF! | F18: =+F17-F14 -> #REF! | G18: =+G17-G14 -> #REF! | H18: =+H17-H14 -> #REF! | I18: =+I17-I14 -> #REF! | J18: =+J17-J14 -> #REF! | K18: =+K17-K14 -> #REF! | L18: =+L17-L14 -> #REF! | M18: =+M17-M14 -> #REF! | N18: =SUM(E18:M18) -> #REF!
