Workbook

Sheet PKL
A1: CREATIVE COLLECTIONS LTD.3
A2: Nishatnagar,Tongi,Gazipur,Dhaka.
A3: PACKING LIST
A4: BULK PACK
F5: SIZE | G5: =G20 -> 25 R | H5: =H20 -> 26 R | I5: =I20 -> 27 R | J5: =J20 -> 28 R | K5: =K20 -> 29 R | L5: =L20 -> 30 R | M5: =M20 -> 31 R | N5: =N20 -> 32 R
F6: N.WT | G6: 0.75 | H6: 0.77 | I6: 0.79 | J6: 0.83 | K6: 0.86 | L6: 0.89 | M6: 0.92 | N6: 0.94
F7: N.N. WT | G7: =+G6-0.03 -> 0.72 | H7: =+H6-0.03 -> 0.74 | I7: =+I6-0.03 -> 0.76 | J7: =+J6-0.03 -> 0.8 | K7: =+K6-0.03 -> 0.83 | L7: =+L6-0.03 -> 0.86 | M7: =+M6-0.03 -> 0.89 | N7: =+N6-0.03 -> 0.91
A8: BUYER : | D8: BANANA REPUBLIC
A9: STYLE : | D9: 1188804014
A10: P. O. # : | D10: 62049433
A11: O/QTY : | D11: =Q43 -> 228 | E11: PCS | N11: PO # | Q11: =D10 -> 62049433
A12: SHIP QTY : | D12: =Q38 -> 228 | E12: PCS | N12: SKU / Item | Q12: =F21 -> 1188804014
A13: EX/SHORT : | D13: =D12-D11 -> 0 | E13: PCS | N13: Unit / Prepack | Q13: 90/45
A14: CTN QTY : | D14: =D38 -> 16 | E14: CTNS | N14: CARTON | Q14: =A21 -> 1 | R14: OF | S14: =D89 -> 32
A15: CTN MEAS. : | D15: 58.67 X 38.48 X 29.72 CM-G81 | N15: CBM | O15: =0.59*0.39*0.3*D40 -> 1.10448
D16: 58.67 X 38.48 X 14.86 CM-G82
D17: 38.48 X 29.34 X 14.86 CM-G84 | P17: DC : BDC-0015
D18: 29.34 X 19.25 X 14.86 CM-G85 | G18: =+G45 -> 0 | H18: =+H45 -> 0 | I18: =+I45 -> 0 | J18: =+J45 -> 0 | K18: =+K45 -> 0 | L18: =+L45 -> 0 | M18: =+M45 -> 0 | N18: =+N45 -> 0
A19: CTN | C19: CTN | D19: CTN QTY | E19: COLOR | F19: PREPACK STECKER | G19: SIZE | P19: QTY PER CTN | Q19: TOTAL QTY | R19: GROSS WEIGHT | S19: NET WEIGHT
A20: NO | C20: MEA | G20: 25 R | H20: 26 R | I20: 27 R | J20: 28 R | K20: 29 R | L20: 30 R | M20: 31 R | N20: 32 R
A21: 1 | B21: =D21+A21-1 -> 1 | C21: G81 | D21: 1 | E21: LIGHT WASH | F21: =+D9 -> 1188804014 | G21: 22 | P21: =SUM(G21:N21) -> 22 | Q21: =P21*D21 -> 22 | R21: =S21+0.91 -> 17.41 | S21: =+G6*P21 -> 16.5 | T21: =+R21*D21 -> 17.41 | X21: 1
A22: =+B21+1 -> 2 | B22: =D22+A22-1 -> 2 | C22: G82 | D22: 1 | G22: 0 | P22: =SUM(G22:N22) -> 0 | Q22: =P22*D22 -> 0 | R22: =S22+0.72 -> 0.72 | S22: =+S21/P21*P22 -> 0 | T22: =+R22*D22 -> 0.72
A23: =+B22+1 -> 3 | B23: =D23+A23-1 -> 3 | C23: G81 | D23: 1 | H23: 24 | P23: =SUM(G23:N23) -> 24 | Q23: =P23*D23 -> 24 | R23: =S23+0.91 -> 19.39 | S23: =++H6*P23 -> 18.48 | T23: =+R23*D23 -> 19.39
A24: =+B23+1 -> 4 | B24: =D24+A24-1 -> 4 | C24: G81 | D24: 1 | H24: 5 | P24: =SUM(G24:N24) -> 5 | Q24: =P24*D24 -> 5 | R24: =S24+0.91 -> 4.76 | S24: =+S23/P23*P24 -> 3.85 | T24: =+R24*D24 -> 4.76
A25: =+B24+1 -> 5 | B25: =D25+A25-1 -> 5 | C25: G81 | D25: 1 | I25: 24 | P25: =SUM(G25:N25) -> 24 | Q25: =P25*D25 -> 24 | R25: =S25+0.91 -> 19.87 | S25: =+I6*P25 -> 18.96 | T25: =+R25*D25 -> 19.87
A26: =+B25+1 -> 6 | B26: =D26+A26-1 -> 6 | C26: G85 | D26: 1 | I26: 14 | P26: =SUM(G26:N26) -> 14 | Q26: =P26*D26 -> 14 | R26: =S26+0.41 -> 11.47 | S26: =+S25/P25*P26 -> 11.06 | T26: =+R26*D26 -> 11.47
A27: =+B26+1 -> 7 | B27: =D27+A27-1 -> 7 | C27: G81 | D27: 1 | J27: 24 | P27: =SUM(G27:N27) -> 24 | Q27: =P27*D27 -> 24 | R27: =S27+0.91 -> 20.83 | S27: =+J6*P27 -> 19.92 | T27: =+R27*D27 -> 20.83
A28: =+B27+1 -> 8 | B28: =D28+A28-1 -> 8 | C28: G84 | D28: 1 | J28: 13 | P28: =SUM(G28:N28) -> 13 | Q28: =P28*D28 -> 13 | R28: =S28+0.41 -> 11.2 | S28: =+S27/P27*P28 -> 10.79 | T28: =+R28*D28 -> 11.2
A29: =+B28+1 -> 9 | B29: =D29+A29-1 -> 9 | C29: G81 | D29: 1 | K29: 22 | P29: =SUM(G29:N29) -> 22 | Q29: =P29*D29 -> 22 | R29: =S29+0.91 -> 19.83 | S29: =+K6*P29 -> 18.92 | T29: =+R29*D29 -> 19.83
A30: =+B29+1 -> 10 | B30: =D30+A30-1 -> 10 | C30: G81 | D30: 1 | K30: 14 | P30: =SUM(G30:N30) -> 14 | Q30: =P30*D30 -> 14 | R30: =S30+0.91 -> 12.95 | S30: =+S29/P29*P30 -> 12.04 | T30: =+R30*D30 -> 12.95
A31: =+B30+1 -> 11 | B31: =D31+A31-1 -> 11 | C31: G81 | D31: 1 | L31: 22 | P31: =SUM(G31:N31) -> 22 | Q31: =P31*D31 -> 22 | R31: =S31+0.91 -> 20.49 | S31: =+L6*P31 -> 19.58 | T31: =+R31*D31 -> 20.49
A32: =+B31+1 -> 12 | B32: =D32+A32-1 -> 12 | C32: G84 | D32: 1 | L32: 5 | P32: =SUM(G32:N32) -> 5 | Q32: =P32*D32 -> 5 | R32: =S32+0.41 -> 4.86 | S32: =+S31/P31*P32 -> 4.45 | T32: =+R32*D32 -> 4.86
A33: =+B32+1 -> 13 | B33: =D33+A33-1 -> 13 | C33: G81 | D33: 1 | M33: 21 | P33: =SUM(G33:N33) -> 21 | Q33: =P33*D33 -> 21 | R33: =S33+0.91 -> 20.23 | S33: =+M6*P33 -> 19.32 | T33: =+R33*D33 -> 20.23
A34: =+B33+1 -> 14 | B34: =D34+A34-1 -> 14 | C34: G82 | D34: 1 | M34: 0 | P34: =SUM(G34:N34) -> 0 | Q34: =P34*D34 -> 0 | R34: =S34+0.72 -> 0.72 | S34: =+S33/P33*P34 -> 0 | T34: =+R34*D34 -> 0.72
A35: =+B34+1 -> 15 | B35: =D35+A35-1 -> 15 | C35: G81 | D35: 1 | N35: 18 | P35: =SUM(G35:N35) -> 18 | Q35: =P35*D35 -> 18 | R35: =S35+0.91 -> 17.83 | S35: =+N6*P35 -> 16.92 | T35: =+R35*D35 -> 17.83
A36: =+B35+1 -> 16 | B36: =D36+A36-1 -> 16 | C36: G82 | D36: 1 | N36: 0 | P36: =SUM(G36:N36) -> 0 | Q36: =P36*D36 -> 0 | R36: =S36+0.72 -> 0.72 | S36: =+S35/P35*P36 -> 0 | T36: =+R36*D36 -> 0.72
X37: 3
A38: TOTAL | D38: =SUM(D21:D37) -> 16 | E38: CTNS | G38: =+Q21+Q22 -> 22 | H38: =+Q23+Q24 -> 29 | I38: =+Q25+Q26 -> 38 | J38: =+Q27+Q28 -> 37 | K38: =+Q29+Q30 -> 36 | L38: =+Q31+Q32 -> 27 | M38: =+Q33+Q34 -> 21 | N38: =+Q35+Q36 -> 18 | Q38: =SUM(Q21:Q37) -> 228 | R38: =SUM(R21:R37) -> 203.28 | T38: =SUM(T21:T37) -> 203.28 | X38: 1
X39: 2
D40: =D38 -> 16 | E40: SUMMARY | U40: 124 | X40: 1
...

Sheet sum
A1: CREATIVE COLLECTIONS LTD.3
A2: Nishat Nagar , Tongi , Gazipur .
A3: PACKING LIST SUMMARY
A5: BUYER | B5: BANANA REPUBLIC
A6: STYLE | B6: =+PKL!D9 -> 1188804014 | G6: DATE | H6: 46295
A8: DC | B8: PO. NO | C8: SEASON | D8: COLOR | E8: ORDER QTY | F8: SHIPT QTY | G8: EXCESS | H8: SHORT | I8: PRE % | J8: TTL CTN QTY
A10: BDC | B10: =+PKL!D10 -> 62049433 | C10: Holl-26 | D10: =+PKL!E21 -> LIGHT WASH | E10: =+PKL!Q43 -> 228 | F10: =+PKL!Q44 -> 228 | G10: =F10-E10 -> 0 | H10: 0 | I10: =G10/E10*100 -> 0 | J10: =+PKL!D40 -> 16
A11: " | B11: " | C11: " | D11: =+PKL!E60 -> TRUFFLE | E11: =+PKL!Q82 -> 228 | F11: =+PKL!Q83 -> 228 | G11: =F11-E11 -> 0 | H11: 0 | I11: =G11/E11*100 -> 0 | J11: =+PKL!D79 -> 16
D12: Total | E12: =SUM(E10:E11) -> 456 | F12: =SUM(F10:F11) -> 456 | G12: =SUM(G10:G11) -> 0 | H12: =SUM(H10:H11) -> 0 | I12: =SUM(I10:I11) -> 0 | J12: =SUM(J10:J11) -> 32
A13: GTO | B13: 62049311 | C13: Spring-26 | D13: LIGHT WASH | E13: 505 | F13: 505 | G13: 0 | H13: 0 | I13: 0 | J13: 43
A14: "" | B14: "" | C14: "" | D14: TRUFFLE | E14: 438 | F14: 438 | G14: 0 | H14: 0 | I14: 0 | J14: 43
D15: Total | E15: =SUM(E13:E14) -> 943 | F15: =SUM(F13:F14) -> 943 | G15: =SUM(G13:G14) -> 0 | H15: =SUM(H13:H14) -> 0 | I15: =SUM(I13:I14) -> 0 | J15: =SUM(J13:J14) -> 86
D17: G.TOTAL= | E17: =SUM(E15,E12) -> 1399 | F17: =SUM(F15,F12) -> 1399 | G17: =SUM(G15,G12) -> 0 | H17: =SUM(H15,H12) -> 0 | I17: =SUM(I15,I12) -> 0 | J17: =SUM(J15,J12) -> 118
B20: SERIAL NO | D20: PENDING ISSUE | E20: YES | F20: NO | G20: REMARKS
B21: 1 | D21: %ISSUE
B22: 2 | D22: GPT
B23: 3 | D23: TOP
B24: 4 | D24: SHADE BAND
B25: 5 | D25: GTS/YTS
B26: 6 | D26: UP DATE DC PO
B27: 7 | D27: TRIM CARD
B28: 8 | D28: FA CTN QTY
B29: 9 | D29: CHECK QTY
B30: 10 | D30: VSL DATE
D31: ITEM | E31: F BLACK OPP JE
A43: FA | C43: PACKING INCHARGE | E43: FINISHING MANAGER
